Traceback (most recent call last):
  File "/home/codespace/.local/lib/python3.12/site-packages/jupyter_core/utils/__init__.py", line 154, in wrapped
    asyncio.get_running_loop()
RuntimeError: no running event loop

During handling of the above exception, another exception occurred:

Traceback (most recent call last):
  File "/home/codespace/.local/lib/python3.12/site-packages/jupyter_cache/executors/utils.py", line 58, in single_nb_execution
    executenb(
  File "/home/codespace/.local/lib/python3.12/site-packages/nbclient/client.py", line 1319, in execute
    return NotebookClient(nb=nb, resources=resources, km=km, **kwargs).execute()
           ^^^^^^^^^^^^^^^^^^^^^^^^^^^^^^^^^^^^^^^^^^^^^^^^^^^^^^^^^^^^^^^^^^^^^
  File "/home/codespace/.local/lib/python3.12/site-packages/jupyter_core/utils/__init__.py", line 158, in wrapped
    return loop.run_until_complete(inner)
           ^^^^^^^^^^^^^^^^^^^^^^^^^^^^^^
  File "/usr/local/python/3.12.1/lib/python3.12/asyncio/base_events.py", line 684, in run_until_complete
    return future.result()
           ^^^^^^^^^^^^^^^
  File "/home/codespace/.local/lib/python3.12/site-packages/nbclient/client.py", line 709, in async_execute
    await self.async_execute_cell(
  File "/home/codespace/.local/lib/python3.12/site-packages/nbclient/client.py", line 1062, in async_execute_cell
    await self._check_raise_for_error(cell, cell_index, exec_reply)
  File "/home/codespace/.local/lib/python3.12/site-packages/nbclient/client.py", line 918, in _check_raise_for_error
    raise CellExecutionError.from_cell_and_msg(cell, exec_reply_content)
nbclient.exceptions.CellExecutionError: An error occurred while executing the following cell:
------------------
open('files/infile1.txt', 'w').write("Avia:Good,Maor:Tel\nAvia:Luck")
open('files/infile2.txt', 'w').write("Maor:Aviv\nMaor:University")

read_msgs(['files/infile1.txt','files/infile2.txt'])
------------------


[31m---------------------------------------------------------------------------[39m
[31mFileNotFoundError[39m                         Traceback (most recent call last)
[36mCell[39m[36m [39m[32mIn[3][39m[32m, line 1[39m
[32m----> [39m[32m1[39m [38;5;28;43mopen[39;49m[43m([49m[33;43m'[39;49m[33;43mfiles/infile1.txt[39;49m[33;43m'[39;49m[43m,[49m[43m [49m[33;43m'[39;49m[33;43mw[39;49m[33;43m'[39;49m[43m)[49m.write([33m"[39m[33mAvia:Good,Maor:Tel[39m[38;5;130;01m\n[39;00m[33mAvia:Luck[39m[33m"[39m)
[32m      2[39m [38;5;28mopen[39m([33m'[39m[33mfiles/infile2.txt[39m[33m'[39m, [33m'[39m[33mw[39m[33m'[39m).write([33m"[39m[33mMaor:Aviv[39m[38;5;130;01m\n[39;00m[33mMaor:University[39m[33m"[39m)
[32m      4[39m read_msgs([[33m'[39m[33mfiles/infile1.txt[39m[33m'[39m,[33m'[39m[33mfiles/infile2.txt[39m[33m'[39m])

[36mFile [39m[32m~/.local/lib/python3.12/site-packages/IPython/core/interactiveshell.py:343[39m, in [36m_modified_open[39m[34m(file, *args, **kwargs)[39m
[32m    336[39m [38;5;28;01mif[39;00m file [38;5;129;01min[39;00m {[32m0[39m, [32m1[39m, [32m2[39m}:
[32m    337[39m     [38;5;28;01mraise[39;00m [38;5;167;01mValueError[39;00m(
[32m    338[39m         [33mf[39m[33m"[39m[33mIPython won[39m[33m'[39m[33mt let you open fd=[39m[38;5;132;01m{[39;00mfile[38;5;132;01m}[39;00m[33m by default [39m[33m"[39m
[32m    339[39m         [33m"[39m[33mas it is likely to crash IPython. If you know what you are doing, [39m[33m"[39m
[32m    340[39m         [33m"[39m[33myou can use builtins[39m[33m'[39m[33m open.[39m[33m"[39m
[32m    341[39m     )
[32m--> [39m[32m343[39m [38;5;28;01mreturn[39;00m [43mio_open[49m[43m([49m[43mfile[49m[43m,[49m[43m [49m[43m*[49m[43margs[49m[43m,[49m[43m [49m[43m*[49m[43m*[49m[43mkwargs[49m[43m)[49m

[31mFileNotFoundError[39m: [Errno 2] No such file or directory: 'files/infile1.txt'

