Traceback (most recent call last):
  File "/home/codespace/.local/lib/python3.12/site-packages/jupyter_core/utils/__init__.py", line 154, in wrapped
    asyncio.get_running_loop()
RuntimeError: no running event loop

During handling of the above exception, another exception occurred:

Traceback (most recent call last):
  File "/home/codespace/.local/lib/python3.12/site-packages/jupyter_cache/executors/utils.py", line 58, in single_nb_execution
    executenb(
  File "/home/codespace/.local/lib/python3.12/site-packages/nbclient/client.py", line 1319, in execute
    return NotebookClient(nb=nb, resources=resources, km=km, **kwargs).execute()
           ^^^^^^^^^^^^^^^^^^^^^^^^^^^^^^^^^^^^^^^^^^^^^^^^^^^^^^^^^^^^^^^^^^^^^
  File "/home/codespace/.local/lib/python3.12/site-packages/jupyter_core/utils/__init__.py", line 158, in wrapped
    return loop.run_until_complete(inner)
           ^^^^^^^^^^^^^^^^^^^^^^^^^^^^^^
  File "/usr/local/python/3.12.1/lib/python3.12/asyncio/base_events.py", line 684, in run_until_complete
    return future.result()
           ^^^^^^^^^^^^^^^
  File "/home/codespace/.local/lib/python3.12/site-packages/nbclient/client.py", line 709, in async_execute
    await self.async_execute_cell(
  File "/home/codespace/.local/lib/python3.12/site-packages/nbclient/client.py", line 1062, in async_execute_cell
    await self._check_raise_for_error(cell, cell_index, exec_reply)
  File "/home/codespace/.local/lib/python3.12/site-packages/nbclient/client.py", line 918, in _check_raise_for_error
    raise CellExecutionError.from_cell_and_msg(cell, exec_reply_content)
nbclient.exceptions.CellExecutionError: An error occurred while executing the following cell:
------------------
# Time comparison for summing over range
def sum_range(start, end):
    s = 0
    for num in range(start, end+1):
        s = s+num
    return s


def sum_range2(start, end):
    return sum(range(start, end+1))

tihs
# Time measurement. You can ignore the code below
import datetime

start=datetime.datetime.now()
res = sum_range(1, 10**8)
end = datetime.datetime.now()

print('The sum of 1+2+...+10**8 is', res, 'and the time it took to compute it is', round((end-start).total_seconds(),2), 'seconds')

------------------


[31m---------------------------------------------------------------------------[39m
[31mNameError[39m                                 Traceback (most recent call last)
[36mCell[39m[36m [39m[32mIn[12][39m[32m, line 12[39m
[32m      9[39m [38;5;28;01mdef[39;00m[38;5;250m [39m[34msum_range2[39m(start, end):
[32m     10[39m     [38;5;28;01mreturn[39;00m [38;5;28msum[39m([38;5;28mrange[39m(start, end+[32m1[39m))
[32m---> [39m[32m12[39m [43mtihs[49m
[32m     13[39m [38;5;66;03m# Time measurement. You can ignore the code below[39;00m
[32m     14[39m [38;5;28;01mimport[39;00m[38;5;250m [39m[34;01mdatetime[39;00m

[31mNameError[39m: name 'tihs' is not defined

