Traceback (most recent call last):
  File "/home/codespace/.local/lib/python3.12/site-packages/jupyter_core/utils/__init__.py", line 154, in wrapped
    asyncio.get_running_loop()
RuntimeError: no running event loop

During handling of the above exception, another exception occurred:

Traceback (most recent call last):
  File "/home/codespace/.local/lib/python3.12/site-packages/jupyter_cache/executors/utils.py", line 58, in single_nb_execution
    executenb(
  File "/home/codespace/.local/lib/python3.12/site-packages/nbclient/client.py", line 1319, in execute
    return NotebookClient(nb=nb, resources=resources, km=km, **kwargs).execute()
           ^^^^^^^^^^^^^^^^^^^^^^^^^^^^^^^^^^^^^^^^^^^^^^^^^^^^^^^^^^^^^^^^^^^^^
  File "/home/codespace/.local/lib/python3.12/site-packages/jupyter_core/utils/__init__.py", line 158, in wrapped
    return loop.run_until_complete(inner)
           ^^^^^^^^^^^^^^^^^^^^^^^^^^^^^^
  File "/usr/local/python/3.12.1/lib/python3.12/asyncio/base_events.py", line 684, in run_until_complete
    return future.result()
           ^^^^^^^^^^^^^^^
  File "/home/codespace/.local/lib/python3.12/site-packages/nbclient/client.py", line 709, in async_execute
    await self.async_execute_cell(
  File "/home/codespace/.local/lib/python3.12/site-packages/nbclient/client.py", line 1062, in async_execute_cell
    await self._check_raise_for_error(cell, cell_index, exec_reply)
  File "/home/codespace/.local/lib/python3.12/site-packages/nbclient/client.py", line 918, in _check_raise_for_error
    raise CellExecutionError.from_cell_and_msg(cell, exec_reply_content)
nbclient.exceptions.CellExecutionError: An error occurred while executing the following cell:
------------------
# Using transpose trick
col_added = (x.T + w).T                # (3,2)->(3,2), then back to (2,3)
print(col_added)

# More direct and readable:
col_added2 = x + w[:, None]            # (2,3) + (2,1) -> (2,3)
print(col_added2)

------------------


[31m---------------------------------------------------------------------------[39m
[31mValueError[39m                                Traceback (most recent call last)
[36mCell[39m[36m [39m[32mIn[46][39m[32m, line 2[39m
[32m      1[39m [38;5;66;03m# Using transpose trick[39;00m
[32m----> [39m[32m2[39m col_added = ([43mx[49m[43m.[49m[43mT[49m[43m [49m[43m+[49m[43m [49m[43mw[49m).T                [38;5;66;03m# (3,2)->(3,2), then back to (2,3)[39;00m
[32m      3[39m [38;5;28mprint[39m(col_added)
[32m      5[39m [38;5;66;03m# More direct and readable:[39;00m

[31mValueError[39m: operands could not be broadcast together with shapes (3,4) (2,) 

