Traceback (most recent call last):
  File "/home/codespace/.local/lib/python3.12/site-packages/jupyter_core/utils/__init__.py", line 154, in wrapped
    asyncio.get_running_loop()
RuntimeError: no running event loop

During handling of the above exception, another exception occurred:

Traceback (most recent call last):
  File "/home/codespace/.local/lib/python3.12/site-packages/jupyter_cache/executors/utils.py", line 58, in single_nb_execution
    executenb(
  File "/home/codespace/.local/lib/python3.12/site-packages/nbclient/client.py", line 1319, in execute
    return NotebookClient(nb=nb, resources=resources, km=km, **kwargs).execute()
           ^^^^^^^^^^^^^^^^^^^^^^^^^^^^^^^^^^^^^^^^^^^^^^^^^^^^^^^^^^^^^^^^^^^^^
  File "/home/codespace/.local/lib/python3.12/site-packages/jupyter_core/utils/__init__.py", line 158, in wrapped
    return loop.run_until_complete(inner)
           ^^^^^^^^^^^^^^^^^^^^^^^^^^^^^^
  File "/usr/local/python/3.12.1/lib/python3.12/asyncio/base_events.py", line 684, in run_until_complete
    return future.result()
           ^^^^^^^^^^^^^^^
  File "/home/codespace/.local/lib/python3.12/site-packages/nbclient/client.py", line 709, in async_execute
    await self.async_execute_cell(
  File "/home/codespace/.local/lib/python3.12/site-packages/nbclient/client.py", line 1062, in async_execute_cell
    await self._check_raise_for_error(cell, cell_index, exec_reply)
  File "/home/codespace/.local/lib/python3.12/site-packages/nbclient/client.py", line 918, in _check_raise_for_error
    raise CellExecutionError.from_cell_and_msg(cell, exec_reply_content)
nbclient.exceptions.CellExecutionError: An error occurred while executing the following cell:
------------------
Ns = np.logspace(2, 6, num=9, base=10, dtype=int)  # from 1e2 to 1e6
est = np.array([mc_pi(int(N), seed=42) for N in Ns])
abs_err = np.abs(est - np.pi)

Ns[:5], est[:3], abs_err[:3]
------------------


[31m---------------------------------------------------------------------------[39m
[31mNameError[39m                                 Traceback (most recent call last)
[36mCell[39m[36m [39m[32mIn[30][39m[32m, line 2[39m
[32m      1[39m Ns = np.logspace([32m2[39m, [32m6[39m, num=[32m9[39m, base=[32m10[39m, dtype=[38;5;28mint[39m)  [38;5;66;03m# from 1e2 to 1e6[39;00m
[32m----> [39m[32m2[39m est = np.array([[43mmc_pi[49m([38;5;28mint[39m(N), seed=[32m42[39m) [38;5;28;01mfor[39;00m N [38;5;129;01min[39;00m Ns])
[32m      3[39m abs_err = np.abs(est - np.pi)
[32m      5[39m Ns[:[32m5[39m], est[:[32m3[39m], abs_err[:[32m3[39m]

[31mNameError[39m: name 'mc_pi' is not defined

